Workbook
Name datatable: verwerking!$A$5:$K$40

Sheet data
A1: hostname: | C1: node1118.muk.os
A2: jobid: | C2: 589521
A4: Benchmark runs OpenBLAS
A6: Variant | B6: nrows | C6: nthreads | D6: time (s) | E6: Gflops | F6: speedup | G6: efficiency (%) | H6: CPU time (s)
A7: OpenBLAS | B7: 2500 | C7: 1 | D7: 1.6379 | E7: 19.0788 | F7: 1 | G7: 100 | H7: 1.62
A8: OpenBLAS | B8: 2500 | C8: 1 | D8: 1.6267 | E8: 19.2105 | F8: 1.007 | G8: 100.6901 | H8: 1.62
A9: OpenBLAS | B9: 2500 | C9: 1 | D9: 1.6269 | E9: 19.2081 | F9: 1.007 | G9: 100.6777 | H9: 1.61
A10: OpenBLAS | B10: 2500 | C10: 1 | D10: 1.6322 | E10: 19.1465 | F10: 1.004 | G10: 100.3546 | H10: 1.62
A11: OpenBLAS | B11: 2500 | C11: 1 | D11: 1.6132 | E11: 19.371 | F11: 1.015 | G11: 101.5313 | H11: 1.62
A12: OpenBLAS | B12: 2500 | C12: 1 | D12: 1.6134 | E12: 19.3695 | F12: 1.015 | G12: 101.5238 | H12: 1.61
A13: OpenBLAS | B13: 2500 | C13: 15 | D13: 0.1273 | E13: 245.4642 | F13: 12.866 | G13: 85.772 | H13: 1.9
A14: OpenBLAS | B14: 2500 | C14: 15 | D14: 0.1234 | E14: 253.1603 | F14: 13.269 | G14: 88.4612 | H14: 1.86
A15: OpenBLAS | B15: 2500 | C15: 15 | D15: 0.1234 | E15: 253.1755 | F15: 13.27 | G15: 88.4665 | H15: 1.85
A16: OpenBLAS | B16: 2500 | C16: 15 | D16: 0.1234 | E16: 253.2062 | F16: 13.272 | G16: 88.4772 | H16: 1.85
A17: OpenBLAS | B17: 2500 | C17: 15 | D17: 0.1235 | E17: 253.0848 | F17: 13.265 | G17: 88.4348 | H17: 1.85
A18: OpenBLAS | B18: 2500 | C18: 15 | D18: 0.1235 | E18: 253.1195 | F18: 13.267 | G18: 88.4469 | H18: 1.86
... A654: OpenBLAS | B654: 10010 | C654: 16 | D654: 6.7948 | E654: 295.2279 | F654: 15.109 | G654: 94.4295 | H654: 108.54
A656: Benchmark runs Intel MKL
A658: Variant | B658: nrows | C658: nthreads | D658: time (s) | E658: Gflops | F658: speedup | G658: efficiency (%) | H658: CPU time (s)
A659: IntelMKL | B659: 2500 | C659: 1 | D659: 1.839 | E659: 16.9926 | F659: 1 | G659: 100 | H659: 7.12
A660: IntelMKL | B660: 2500 | C660: 1 | D660: 1.6035 | E660: 19.488 | F660: 1.147 | G660: 114.6857 | H660: 1.6
A661: IntelMKL | B661: 2500 | C661: 1 | D661: 1.6034 | E661: 19.4895 | F661: 1.147 | G661: 114.6942 | H661: 1.61
A662: IntelMKL | B662: 2500 | C662: 1 | D662: 1.6035 | E662: 19.4889 | F662: 1.147 | G662: 114.691 | H662: 1.6
A663: IntelMKL | B663: 2500 | C663: 1 | D663: 1.6035 | E663: 19.4891 | F663: 1.147 | G663: 114.6923 | H663: 1.6
A664: IntelMKL | B664: 2500 | C664: 1 | D664: 1.6034 | E664: 19.4899 | F664: 1.147 | G664: 114.6967 | H664: 1.61
A665: IntelMKL | B665: 2500 | C665: 15 | D665: 0.1258 | E665: 248.4754 | F665: 14.623 | G665: 97.484 | H665: 1.88
A666: IntelMKL | B666: 2500 | C666: 15 | D666: 0.124 | E666: 251.9836 | F666: 14.829 | G666: 98.8604 | H666: 1.85
A667: IntelMKL | B667: 2500 | C667: 15 | D667: 0.1241 | E667: 251.8983 | F667: 14.824 | G667: 98.8269 | H667: 1.85
A668: IntelMKL | B668: 2500 | C668: 15 | D668: 0.1241 | E668: 251.7988 | F668: 14.818 | G668: 98.7879 | H668: 1.86
A669: IntelMKL | B669: 2500 | C669: 15 | D669: 0.124 | E669: 251.9308 | F669: 14.826 | G669: 98.8397 | H669: 1.86
A670: IntelMKL | B670: 2500 | C670: 15 | D670: 0.124 | E670: 252.0304 | F670: 14.832 | G670: 98.8788 | H670: 1.85
... A1306: IntelMKL | B1306: 10010 | C1306: 16 | D1306: 6.6135 | E1306: 303.3214 | F1306: 15.513 | G1306: 96.9548 | H1306: 105.7197

Sheet verwerking
B1: Compute node: | D1: =data!C1 -> node1118.muk.os
E3: Time | I3: Gflops
A4: Key | B4: Variant | C4: Nrows | D4: Threads | E4: gemiddelde | F4: min | G4: max | H4: speling | I4: gemiddelde | J4: min | K4: max | N4: Variant | O4: Nrows | P4: Threads | Q4: Start | R4: Number | S4: Check NR | T4: Check Th
A5: =N5 & TEXT($O5,"000000") & TEXT($P5, "000") -> OpenBLAS002500001 | B5: =N5 -> OpenBLAS | C5: =O5 -> 2500 | D5: =P5 -> 1 | E5: =AVERAGE(OFFSET(data!$A$1,$Q5-1,3,$R5,1)) -> 1.62248 | F5: =MIN(OFFSET(data!$A$1,$Q5-1,3,$R5,1)) -> 1.6132 | G5: =MAX(OFFSET(data!$A$1,$Q5-1,3,$R5,1)) -> 1.6322 | H5: =(G5-F5)/E5 -> 0.011710468 | I5: =AVERAGE(OFFSET(data!$A$1,$Q5-1,4,$R5,1)) -> 19.26112 | J5: =MIN(OFFSET(data!$A$1,$Q5-1,4,$R5,1)) -> 19.1465 | K5: =MAX(OFFSET(data!$A$1,$Q5-1,4,$R5,1)) -> 19.371 | N5: =OFFSET(data!$A$1,$Q5-1,0) -> OpenBLAS | O5: =OFFSET(data!$A$1,$Q5-1,1) -> 2500 | P5: =OFFSET(data!$A$1,$Q5-1,2) -> 1 | Q5: 8 | R5: 5 | S5: =IF(AVERAGE(OFFSET(data!$A$1,$Q5,1,$R5-1,1))=O5,1,0) -> 1 | T5: =IF(AVERAGE(OFFSET(data!$A$1,$Q5,2,$R5-1,1))=P5,1,0) -> 1
A6: =N6 & TEXT($O6,"000000") & TEXT($P6, "000") -> OpenBLAS002500015 | B6: =N6 -> OpenBLAS | C6: =O6 -> 2500 | D6: =P6 -> 15 | E6: =AVERAGE(OFFSET(data!$A$1,$Q6-1,3,$R6,1)) -> 0.124174 | F6: =MIN(OFFSET(data!$A$1,$Q6-1,3,$R6,1)) -> 0.1233 | G6: =MAX(OFFSET(data!$A$1,$Q6-1,3,$R6,1)) -> 0.1293 | H6: =(G6-F6)/E6 -> 0.048319294 | I6: =AVERAGE(OFFSET(data!$A$1,$Q6-1,4,$R6,1)) -> 251.70313 | J6: =MIN(OFFSET(data!$A$1,$Q6-1,4,$R6,1)) -> 241.7672 | K6: =MAX(OFFSET(data!$A$1,$Q6-1,4,$R6,1)) -> 253.4247 | N6: =OFFSET(data!$A$1,$Q6-1,0) -> OpenBLAS | O6: =OFFSET(data!$A$1,$Q6-1,1) -> 2500 | P6: =OFFSET(data!$A$1,$Q6-1,2) -> 15 | Q6: =Q5+R5+1 -> 14 | R6: 50 | S6: =IF(AVERAGE(OFFSET(data!$A$1,$Q6,1,$R6-1,1))=O6,1,0) -> 1 | T6: =IF(AVERAGE(OFFSET(data!$A$1,$Q6,2,$R6-1,1))=P6,1,0) -> 1
A7: =N7 & TEXT($O7,"000000") & TEXT($P7, "000") -> OpenBLAS002500016 | B7: =N7 -> OpenBLAS | C7: =O7 -> 2500 | D7: =P7 -> 16 | E7: =AVERAGE(OFFSET(data!$A$1,$Q7-1,3,$R7,1)) -> 0.202552 | F7: =MIN(OFFSET(data!$A$1,$Q7-1,3,$R7,1)) -> 0.1145 | G7: =MAX(OFFSET(data!$A$1,$Q7-1,3,$R7,1)) -> 0.2291 | H7: =(G7-F7)/E7 -> 0.56578064 | I7: =AVERAGE(OFFSET(data!$A$1,$Q7-1,4,$R7,1)) -> 160.7458 | J7: =MIN(OFFSET(data!$A$1,$Q7-1,4,$R7,1)) -> 136.4245 | K7: =MAX(OFFSET(data!$A$1,$Q7-1,4,$R7,1)) -> 272.895 | N7: =OFFSET(data!$A$1,$Q7-1,0) -> OpenBLAS | O7: =OFFSET(data!$A$1,$Q7-1,1) -> 2500 | P7: =OFFSET(data!$A$1,$Q7-1,2) -> 16 | Q7: =Q6+R6+1 -> 65 | R7: 50 | S7: =IF(AVERAGE(OFFSET(data!$A$1,$Q7,1,$R7-1,1))=O7,1,0) -> 1 | T7: =IF(AVERAGE(OFFSET(data!$A$1,$Q7,2,$R7-1,1))=P7,1,0) -> 1
A8: =N8 & TEXT($O8,"000000") & TEXT($P8, "000") -> OpenBLAS002505001 | B8: =N8 -> OpenBLAS | C8: =O8 -> 2505 | D8: =P8 -> 1 | E8: =AVERAGE(OFFSET(data!$A$1,$Q8-1,3,$R8,1)) -> 1.63118 | F8: =MIN(OFFSET(data!$A$1,$Q8-1,3,$R8,1)) -> 1.6311 | G8: =MAX(OFFSET(data!$A$1,$Q8-1,3,$R8,1)) -> 1.6312 | H8: =(G8-F8)/E8 -> 6.1305313e-05 | I8: =AVERAGE(OFFSET(data!$A$1,$Q8-1,4,$R8,1)) -> 19.27274 | J8: =MIN(OFFSET(data!$A$1,$Q8-1,4,$R8,1)) -> 19.2723 | K8: =MAX(OFFSET(data!$A$1,$Q8-1,4,$R8,1)) -> 19.2738 | N8: =OFFSET(data!$A$1,$Q8-1,0) -> OpenBLAS | O8: =OFFSET(data!$A$1,$Q8-1,1) -> 2505 | P8: =OFFSET(data!$A$1,$Q8-1,2) -> 1 | Q8: =Q7+R7+1 -> 116 | R8: 5 | S8: =IF(AVERAGE(OFFSET(data!$A$1,$Q8,1,$R8-1,1))=O8,1,0) -> 1 | T8: =IF(AVERAGE(OFFSET(data!$A$1,$Q8,2,$R8-1,1))=P8,1,0) -> 1
A9: =N9 & TEXT($O9,"000000") & TEXT($P9, "000") -> OpenBLAS002505015 | B9: =N9 -> OpenBLAS | C9: =O9 -> 2505 | D9: =P9 -> 15 | E9: =AVERAGE(OFFSET(data!$A$1,$Q9-1,3,$R9,1)) -> 0.12412 | F9: =MIN(OFFSET(data!$A$1,$Q9-1,3,$R9,1)) -> 0.1232 | G9: =MAX(OFFSET(data!$A$1,$Q9-1,3,$R9,1)) -> 0.1258 | H9: =(G9-F9)/E9 -> 0.02094747 | I9: =AVERAGE(OFFSET(data!$A$1,$Q9-1,4,$R9,1)) -> 253.28069 | J9: =MIN(OFFSET(data!$A$1,$Q9-1,4,$R9,1)) -> 249.8296 | K9: =MAX(OFFSET(data!$A$1,$Q9-1,4,$R9,1)) -> 255.2581 | N9: =OFFSET(data!$A$1,$Q9-1,0) -> OpenBLAS | O9: =OFFSET(data!$A$1,$Q9-1,1) -> 2505 | P9: =OFFSET(data!$A$1,$Q9-1,2) -> 15 | Q9: =Q8+R8+1 -> 122 | R9: 50 | S9: =IF(AVERAGE(OFFSET(data!$A$1,$Q9,1,$R9-1,1))=O9,1,0) -> 1 | T9: =IF(AVERAGE(OFFSET(data!$A$1,$Q9,2,$R9-1,1))=P9,1,0) -> 1
A10: =N10 & TEXT($O10,"000000") & TEXT($P10, "000") -> OpenBLAS002505016 | B10: =N10 -> OpenBLAS | C10: =O10 -> 2505 | D10: =P10 -> 16 | E10: =AVERAGE(OFFSET(data!$A$1,$Q10-1,3,$R10,1)) -> 0.117566 | F10: =MIN(OFFSET(data!$A$1,$Q10-1,3,$R10,1)) -> 0.1161 | G10: =MAX(OFFSET(data!$A$1,$Q10-1,3,$R10,1)) -> 0.1331 | H10: =(G10-F10)/E10 -> 0.14459963 | I10: =AVERAGE(OFFSET(data!$A$1,$Q10-1,4,$R10,1)) -> 267.63091 | J10: =MIN(OFFSET(data!$A$1,$Q10-1,4,$R10,1)) -> 236.1893 | K10: =MAX(OFFSET(data!$A$1,$Q10-1,4,$R10,1)) -> 270.8255 | N10: =OFFSET(data!$A$1,$Q10-1,0) -> OpenBLAS | O10: =OFFSET(data!$A$1,$Q10-1,1) -> 2505 | P10: =OFFSET(data!$A$1,$Q10-1,2) -> 16 | Q10: =Q9+R9+1 -> 173 | R10: 50 | S10: =IF(AVERAGE(OFFSET(data!$A$1,$Q10,1,$R10-1,1))=O10,1,0) -> 1 | T10: =IF(AVERAGE(OFFSET(data!$A$1,$Q10,2,$R10-1,1))=P10,1,0) -> 1
A11: =N11 & TEXT($O11,"000000") & TEXT($P11, "000") -> OpenBLAS002510001 | B11: =N11 -> OpenBLAS | C11: =O11 -> 2510 | D11: =P11 -> 1 | E11: =AVERAGE(OFFSET(data!$A$1,$Q11-1,3,$R11,1)) -> 1.62912 | F11: =MIN(OFFSET(data!$A$1,$Q11-1,3,$R11,1)) -> 1.629 | G11: =MAX(OFFSET(data!$A$1,$Q11-1,3,$R11,1)) -> 1.6292 | H11: =(G11-F11)/E11 -> 0.00012276566 | I11: =AVERAGE(OFFSET(data!$A$1,$Q11-1,4,$R11,1)) -> 19.41332 | J11: =MIN(OFFSET(data!$A$1,$Q11-1,4,$R11,1)) -> 19.4124 | K11: =MAX(OFFSET(data!$A$1,$Q11-1,4,$R11,1)) -> 19.4141 | N11: =OFFSET(data!$A$1,$Q11-1,0) -> OpenBLAS | O11: =OFFSET(data!$A$1,$Q11-1,1) -> 2510 | P11: =OFFSET(data!$A$1,$Q11-1,2) -> 1 | Q11: =Q10+R10+1 -> 224 | R11: 5 | S11: =IF(AVERAGE(OFFSET(data!$A$1,$Q11,1,$R11-1,1))=O11,1,0) -> 1 | T11: =IF(AVERAGE(OFFSET(data!$A$1,$Q11,2,$R11-1,1))=P11,1,0) -> 1
A12: =N12 & TEXT($O12,"000000") & TEXT($P12, "000") -> OpenBLAS002510015 | B12: =N12 -> OpenBLAS | C12: =O12 -> 2510 | D12: =P12 -> 15 | E12: =AVERAGE(OFFSET(data!$A$1,$Q12-1,3,$R12,1)) -> 0.122194 | F12: =MIN(OFFSET(data!$A$1,$Q12-1,3,$R12,1)) -> 0.1217 | G12: =MAX(OFFSET(data!$A$1,$Q12-1,3,$R12,1)) -> 0.1226 | H12: =(G12-F12)/E12 -> 0.0073653371 | I12: =AVERAGE(OFFSET(data!$A$1,$Q12-1,4,$R12,1)) -> 258.82319 | J12: =MIN(OFFSET(data!$A$1,$Q12-1,4,$R12,1)) -> 257.9523 | K12: =MAX(OFFSET(data!$A$1,$Q12-1,4,$R12,1)) -> 259.8942 | N12: =OFFSET(data!$A$1,$Q12-1,0) -> OpenBLAS | O12: =OFFSET(data!$A$1,$Q12-1,1) -> 2510 | P12: =OFFSET(data!$A$1,$Q12-1,2) -> 15 | Q12: =Q11+R11+1 -> 230 | R12: 50 | S12: =IF(AVERAGE(OFFSET(data!$A$1,$Q12,1,$R12-1,1))=O12,1,0) -> 1 | T12: =IF(AVERAGE(OFFSET(data!$A$1,$Q12,2,$R12-1,1))=P12,1,0) -> 1
A13: =N13 & TEXT($O13,"000000") & TEXT($P13, "000") -> OpenBLAS002510016 | B13: =N13 -> OpenBLAS | C13: =O13 -> 2510 | D13: =P13 -> 16 | E13: =AVERAGE(OFFSET(data!$A$1,$Q13-1,3,$R13,1)) -> 0.119038 | F13: =MIN(OFFSET(data!$A$1,$Q13-1,3,$R13,1)) -> 0.1183 | G13: =MAX(OFFSET(data!$A$1,$Q13-1,3,$R13,1)) -> 0.1259 | H13: =(G13-F13)/E13 -> 0.063845159 | I13: =AVERAGE(OFFSET(data!$A$1,$Q13-1,4,$R13,1)) -> 265.71807 | J13: =MIN(OFFSET(data!$A$1,$Q13-1,4,$R13,1)) -> 251.145 | K13: =MAX(OFFSET(data!$A$1,$Q13-1,4,$R13,1)) -> 267.2455 | N13: =OFFSET(data!$A$1,$Q13-1,0) -> OpenBLAS | O13: =OFFSET(data!$A$1,$Q13-1,1) -> 2510 | P13: =OFFSET(data!$A$1,$Q13-1,2) -> 16 | Q13: =Q12+R12+1 -> 281 | R13: 50 | S13: =IF(AVERAGE(OFFSET(data!$A$1,$Q13,1,$R13-1,1))=O13,1,0) -> 1 | T13: =IF(AVERAGE(OFFSET(data!$A$1,$Q13,2,$R13-1,1))=P13,1,0) -> 1
A14: =N14 & TEXT($O14,"000000") & TEXT($P14, "000") -> OpenBLAS010000001 | B14: =N14 -> OpenBLAS | C14: =O14 -> 10000 | D14: =P14 -> 1 | E14: =AVERAGE(OFFSET(data!$A$1,$Q14-1,3,$R14,1)) -> 102.48744 | F14: =MIN(OFFSET(data!$A$1,$Q14-1,3,$R14,1)) -> 102.3207 | G14: =MAX(OFFSET(data!$A$1,$Q14-1,3,$R14,1)) -> 102.8214 | H14: =(G14-F14)/E14 -> 0.0048854767 | I14: =AVERAGE(OFFSET(data!$A$1,$Q14-1,4,$R14,1)) -> 19.51466 | J14: =MIN(OFFSET(data!$A$1,$Q14-1,4,$R14,1)) -> 19.4512 | K14: =MAX(OFFSET(data!$A$1,$Q14-1,4,$R14,1)) -> 19.5464 | N14: =OFFSET(data!$A$1,$Q14-1,0) -> OpenBLAS | O14: =OFFSET(data!$A$1,$Q14-1,1) -> 10000 | P14: =OFFSET(data!$A$1,$Q14-1,2) -> 1 | Q14: =Q13+R13+1 -> 332 | R14: 5 | S14: =IF(AVERAGE(OFFSET(data!$A$1,$Q14,1,$R14-1,1))=O14,1,0) -> 1 | T14: =IF(AVERAGE(OFFSET(data!$A$1,$Q14,2,$R14-1,1))=P14,1,0) -> 1
A15: =N15 & TEXT($O15,"000000") & TEXT($P15, "000") -> OpenBLAS010000015 | B15: =N15 -> OpenBLAS | C15: =O15 -> 10000 | D15: =P15 -> 15 | E15: =AVERAGE(OFFSET(data!$A$1,$Q15-1,3,$R15,1)) -> 7.194956 | F15: =MIN(OFFSET(data!$A$1,$Q15-1,3,$R15,1)) -> 7.1694 | G15: =MAX(OFFSET(data!$A$1,$Q15-1,3,$R15,1)) -> 7.2176 | H15: =(G15-F15)/E15 -> 0.0066991376 | I15: =AVERAGE(OFFSET(data!$A$1,$Q15-1,4,$R15,1)) -> 277.97333 | J15: =MIN(OFFSET(data!$A$1,$Q15-1,4,$R15,1)) -> 277.1015 | K15: =MAX(OFFSET(data!$A$1,$Q15-1,4,$R15,1)) -> 278.9632 | N15: =OFFSET(data!$A$1,$Q15-1,0) -> OpenBLAS | O15: =OFFSET(data!$A$1,$Q15-1,1) -> 10000 | P15: =OFFSET(data!$A$1,$Q15-1,2) -> 15 | Q15: =Q14+R14+1 -> 338 | R15: 50 | S15: =IF(AVERAGE(OFFSET(data!$A$1,$Q15,1,$R15-1,1))=O15,1,0) -> 1 | T15: =IF(AVERAGE(OFFSET(data!$A$1,$Q15,2,$R15-1,1))=P15,1,0) -> 1
A16: =N16 & TEXT($O16,"000000") & TEXT($P16, "000") -> OpenBLAS010000016 | B16: =N16 -> OpenBLAS | C16: =O16 -> 10000 | D16: =P16 -> 16 | E16: =AVERAGE(OFFSET(data!$A$1,$Q16-1,3,$R16,1)) -> 6.988962 | F16: =MIN(OFFSET(data!$A$1,$Q16-1,3,$R16,1)) -> 6.7944 | G16: =MAX(OFFSET(data!$A$1,$Q16-1,3,$R16,1)) -> 11.8652 | H16: =(G16-F16)/E16 -> 0.72554408 | I16: =AVERAGE(OFFSET(data!$A$1,$Q16-1,4,$R16,1)) -> 288.90371 | J16: =MIN(OFFSET(data!$A$1,$Q16-1,4,$R16,1)) -> 168.56 | K16: =MAX(OFFSET(data!$A$1,$Q16-1,4,$R16,1)) -> 294.3592 | N16: =OFFSET(data!$A$1,$Q16-1,0) -> OpenBLAS | O16: =OFFSET(data!$A$1,$Q16-1,1) -> 10000 | P16: =OFFSET(data!$A$1,$Q16-1,2) -> 16 | Q16: =Q15+R15+1 -> 389 | R16: 50 | S16: =IF(AVERAGE(OFFSET(data!$A$1,$Q16,1,$R16-1,1))=O16,1,0) -> 1 | T16: =IF(AVERAGE(OFFSET(data!$A$1,$Q16,2,$R16-1,1))=P16,1,0) -> 1
A17: =N17 & TEXT($O17,"000000") & TEXT($P17, "000") -> OpenBLAS010005001 | B17: =N17 -> OpenBLAS | C17: =O17 -> 10005 | D17: =P17 -> 1 | E17: =AVERAGE(OFFSET(data!$A$1,$Q17-1,3,$R17,1)) -> 103.20922 | F17: =MIN(OFFSET(data!$A$1,$Q17-1,3,$R17,1)) -> 103.2062 | G17: =MAX(OFFSET(data!$A$1,$Q17-1,3,$R17,1)) -> 103.2142 | H17: =(G17-F17)/E17 -> 7.7512455e-05 | I17: =AVERAGE(OFFSET(data!$A$1,$Q17-1,4,$R17,1)) -> 19.4072 | J17: =MIN(OFFSET(data!$A$1,$Q17-1,4,$R17,1)) -> 19.4063 | K17: =MAX(OFFSET(data!$A$1,$Q17-1,4,$R17,1)) -> 19.4078 | N17: =OFFSET(data!$A$1,$Q17-1,0) -> OpenBLAS | O17: =OFFSET(data!$A$1,$Q17-1,1) -> 10005 | P17: =OFFSET(data!$A$1,$Q17-1,2) -> 1 | Q17: =Q16+R16+1 -> 440 | R17: 5 | S17: =IF(AVERAGE(OFFSET(data!$A$1,$Q17,1,$R17-1,1))=O17,1,0) -> 1 | T17: =IF(AVERAGE(OFFSET(data!$A$1,$Q17,2,$R17-1,1))=P17,1,0) -> 1
... A22: =N22 & TEXT($O22,"000000") & TEXT($P22, "000") -> OpenBLAS010010016 | B22: =N22 -> OpenBLAS | C22: =O22 -> 10010 | D22: =P22 -> 16 | E22: =AVERAGE(OFFSET(data!$A$1,$Q22-1,3,$R22,1)) -> 6.94926 | F22: =MIN(OFFSET(data!$A$1,$Q22-1,3,$R22,1)) -> 6.7729 | G22: =MAX(OFFSET(data!$A$1,$Q22-1,3,$R22,1)) -> 11.6832 | H22: =(G22-F22)/E22 -> 0.70659322 | I22: =AVERAGE(OFFSET(data!$A$1,$Q22-1,4,$R22,1)) -> 291.31797 | J22: =MIN(OFFSET(data!$A$1,$Q22-1,4,$R22,1)) -> 171.7005 | K22: =MAX(OFFSET(data!$A$1,$Q22-1,4,$R22,1)) -> 296.1798 | N22: =OFFSET(data!$A$1,$Q22-1,0) -> OpenBLAS | O22: =OFFSET(data!$A$1,$Q22-1,1) -> 10010 | P22: =OFFSET(data!$A$1,$Q22-1,2) -> 16 | Q22: =Q21+R21+1 -> 605 | R22: 50 | S22: =IF(AVERAGE(OFFSET(data!$A$1,$Q22,1,$R22-1,1))=O22,1,0) -> 1 | T22: =IF(AVERAGE(OFFSET(data!$A$1,$Q22,2,$R22-1,1))=P22,1,0) -> 1
A23: =N23 & TEXT($O23,"000000") & TEXT($P23, "000") -> IntelMKL002500001 | B23: =N23 -> IntelMKL | C23: =O23 -> 2500 | D23: =P23 -> 1 | E23: =AVERAGE(OFFSET(data!$A$1,$Q23-1,3,$R23,1)) -> 1.60346 | F23: =MIN(OFFSET(data!$A$1,$Q23-1,3,$R23,1)) -> 1.6034 | G23: =MAX(OFFSET(data!$A$1,$Q23-1,3,$R23,1)) -> 1.6035 | H23: =(G23-F23)/E23 -> 6.2365135e-05 | I23: =AVERAGE(OFFSET(data!$A$1,$Q23-1,4,$R23,1)) -> 19.48908 | J23: =MIN(OFFSET(data!$A$1,$Q23-1,4,$R23,1)) -> 19.488 | K23: =MAX(OFFSET(data!$A$1,$Q23-1,4,$R23,1)) -> 19.4899 | N23: =OFFSET(data!$A$1,$Q23-1,0) -> IntelMKL | O23: =OFFSET(data!$A$1,$Q23-1,1) -> 2500 | P23: =OFFSET(data!$A$1,$Q23-1,2) -> 1 | Q23: 660 | R23: 5 | S23: =IF(AVERAGE(OFFSET(data!$A$1,$Q23,1,$R23-1,1))=O23,1,0) -> 1 | T23: =IF(AVERAGE(OFFSET(data!$A$1,$Q23,2,$R23-1,1))=P23,1,0) -> 1
A24: =N24 & TEXT($O24,"000000") & TEXT($P24, "000") -> IntelMKL002500015 | B24: =N24 -> IntelMKL | C24: =O24 -> 2500 | D24: =P24 -> 15 | E24: =AVERAGE(OFFSET(data!$A$1,$Q24-1,3,$R24,1)) -> 0.124078 | F24: =MIN(OFFSET(data!$A$1,$Q24-1,3,$R24,1)) -> 0.124 | G24: =MAX(OFFSET(data!$A$1,$Q24-1,3,$R24,1)) -> 0.1243 | H24: =(G24-F24)/E24 -> 0.0024178339 | I24: =AVERAGE(OFFSET(data!$A$1,$Q24-1,4,$R24,1)) -> 251.86468 | J24: =MIN(OFFSET(data!$A$1,$Q24-1,4,$R24,1)) -> 251.3978 | K24: =MAX(OFFSET(data!$A$1,$Q24-1,4,$R24,1)) -> 252.0304 | N24: =OFFSET(data!$A$1,$Q24-1,0) -> IntelMKL | O24: =OFFSET(data!$A$1,$Q24-1,1) -> 2500 | P24: =OFFSET(data!$A$1,$Q24-1,2) -> 15 | Q24: =Q23+R23+1 -> 666 | R24: 50 | S24: =IF(AVERAGE(OFFSET(data!$A$1,$Q24,1,$R24-1,1))=O24,1,0) -> 1 | T24: =IF(AVERAGE(OFFSET(data!$A$1,$Q24,2,$R24-1,1))=P24,1,0) -> 1
A25: =N25 & TEXT($O25,"000000") & TEXT($P25, "000") -> IntelMKL002500016 | B25: =N25 -> IntelMKL | C25: =O25 -> 2500 | D25: =P25 -> 16 | E25: =AVERAGE(OFFSET(data!$A$1,$Q25-1,3,$R25,1)) -> 0.111076 | F25: =MIN(OFFSET(data!$A$1,$Q25-1,3,$R25,1)) -> 0.1097 | G25: =MAX(OFFSET(data!$A$1,$Q25-1,3,$R25,1)) -> 0.1136 | H25: =(G25-F25)/E25 -> 0.035111095 | I25: =AVERAGE(OFFSET(data!$A$1,$Q25-1,4,$R25,1)) -> 281.34522 | J25: =MIN(OFFSET(data!$A$1,$Q25-1,4,$R25,1)) -> 275.0783 | K25: =MAX(OFFSET(data!$A$1,$Q25-1,4,$R25,1)) -> 284.951 | N25: =OFFSET(data!$A$1,$Q25-1,0) -> IntelMKL | O25: =OFFSET(data!$A$1,$Q25-1,1) -> 2500 | P25: =OFFSET(data!$A$1,$Q25-1,2) -> 16 | Q25: =Q24+R24+1 -> 717 | R25: 50 | S25: =IF(AVERAGE(OFFSET(data!$A$1,$Q25,1,$R25-1,1))=O25,1,0) -> 1 | T25: =IF(AVERAGE(OFFSET(data!$A$1,$Q25,2,$R25-1,1))=P25,1,0) -> 1
A26: =N26 & TEXT($O26,"000000") & TEXT($P26, "000") -> IntelMKL002505001 | B26: =N26 -> IntelMKL | C26: =O26 -> 2505 | D26: =P26 -> 1 | E26: =AVERAGE(OFFSET(data!$A$1,$Q26-1,3,$R26,1)) -> 1.61956 | F26: =MIN(OFFSET(data!$A$1,$Q26-1,3,$R26,1)) -> 1.6195 | G26: =MAX(OFFSET(data!$A$1,$Q26-1,3,$R26,1)) -> 1.6196 | H26: =(G26-F26)/E26 -> 6.1745165e-05 | I26: =AVERAGE(OFFSET(data!$A$1,$Q26-1,4,$R26,1)) -> 19.4114 | J26: =MIN(OFFSET(data!$A$1,$Q26-1,4,$R26,1)) -> 19.4104 | K26: =MAX(OFFSET(data!$A$1,$Q26-1,4,$R26,1)) -> 19.4121 | N26: =OFFSET(data!$A$1,$Q26-1,0) -> IntelMKL | O26: =OFFSET(data!$A$1,$Q26-1,1) -> 2505 | P26: =OFFSET(data!$A$1,$Q26-1,2) -> 1 | Q26: =Q25+R25+1 -> 768 | R26: 5 | S26: =IF(AVERAGE(OFFSET(data!$A$1,$Q26,1,$R26-1,1))=O26,1,0) -> 1 | T26: =IF(AVERAGE(OFFSET(data!$A$1,$Q26,2,$R26-1,1))=P26,1,0) -> 1
A27: =N27 & TEXT($O27,"000000") & TEXT($P27, "000") -> IntelMKL002505015 | B27: =N27 -> IntelMKL | C27: =O27 -> 2505 | D27: =P27 -> 15 | E27: =AVERAGE(OFFSET(data!$A$1,$Q27-1,3,$R27,1)) -> 0.124926 | F27: =MIN(OFFSET(data!$A$1,$Q27-1,3,$R27,1)) -> 0.1248 | G27: =MAX(OFFSET(data!$A$1,$Q27-1,3,$R27,1)) -> 0.13 | H27: =(G27-F27)/E27 -> 0.041624642 | I27: =AVERAGE(OFFSET(data!$A$1,$Q27-1,4,$R27,1)) -> 251.62397 | J27: =MIN(OFFSET(data!$A$1,$Q27-1,4,$R27,1)) -> 241.7684 | K27: =MAX(OFFSET(data!$A$1,$Q27-1,4,$R27,1)) -> 251.9101 | N27: =OFFSET(data!$A$1,$Q27-1,0) -> IntelMKL | O27: =OFFSET(data!$A$1,$Q27-1,1) -> 2505 | P27: =OFFSET(data!$A$1,$Q27-1,2) -> 15 | Q27: =Q26+R26+1 -> 774 | R27: 50 | S27: =IF(AVERAGE(OFFSET(data!$A$1,$Q27,1,$R27-1,1))=O27,1,0) -> 1 | T27: =IF(AVERAGE(OFFSET(data!$A$1,$Q27,2,$R27-1,1))=P27,1,0) -> 1
A28: =N28 & TEXT($O28,"000000") & TEXT($P28, "000") -> IntelMKL002505016 | B28: =N28 -> IntelMKL | C28: =O28 -> 2505 | D28: =P28 -> 16 | E28: =AVERAGE(OFFSET(data!$A$1,$Q28-1,3,$R28,1)) -> 0.112786 | F28: =MIN(OFFSET(data!$A$1,$Q28-1,3,$R28,1)) -> 0.1118 | G28: =MAX(OFFSET(data!$A$1,$Q28-1,3,$R28,1)) -> 0.1144 | H28: =(G28-F28)/E28 -> 0.023052507 | I28: =AVERAGE(OFFSET(data!$A$1,$Q28-1,4,$R28,1)) -> 278.73924 | J28: =MIN(OFFSET(data!$A$1,$Q28-1,4,$R28,1)) -> 274.8306 | K28: =MAX(OFFSET(data!$A$1,$Q28-1,4,$R28,1)) -> 281.0893 | N28: =OFFSET(data!$A$1,$Q28-1,0) -> IntelMKL | O28: =OFFSET(data!$A$1,$Q28-1,1) -> 2505 | P28: =OFFSET(data!$A$1,$Q28-1,2) -> 16 | Q28: =Q27+R27+1 -> 825 | R28: 50 | S28: =IF(AVERAGE(OFFSET(data!$A$1,$Q28,1,$R28-1,1))=O28,1,0) -> 1 | T28: =IF(AVERAGE(OFFSET(data!$A$1,$Q28,2,$R28-1,1))=P28,1,0) -> 1
A29: =N29 & TEXT($O29,"000000") & TEXT($P29, "000") -> IntelMKL002510001 | B29: =N29 -> IntelMKL | C29: =O29 -> 2510 | D29: =P29 -> 1 | E29: =AVERAGE(OFFSET(data!$A$1,$Q29-1,3,$R29,1)) -> 1.61324 | F29: =MIN(OFFSET(data!$A$1,$Q29-1,3,$R29,1)) -> 1.6132 | G29: =MAX(OFFSET(data!$A$1,$Q29-1,3,$R29,1)) -> 1.6133 | H29: =(G29-F29)/E29 -> 6.1987057e-05 | I29: =AVERAGE(OFFSET(data!$A$1,$Q29-1,4,$R29,1)) -> 19.60426 | J29: =MIN(OFFSET(data!$A$1,$Q29-1,4,$R29,1)) -> 19.6035 | K29: =MAX(OFFSET(data!$A$1,$Q29-1,4,$R29,1)) -> 19.6049 | N29: =OFFSET(data!$A$1,$Q29-1,0) -> IntelMKL | O29: =OFFSET(data!$A$1,$Q29-1,1) -> 2510 | P29: =OFFSET(data!$A$1,$Q29-1,2) -> 1 | Q29: =Q28+R28+1 -> 876 | R29: 5 | S29: =IF(AVERAGE(OFFSET(data!$A$1,$Q29,1,$R29-1,1))=O29,1,0) -> 1 | T29: =IF(AVERAGE(OFFSET(data!$A$1,$Q29,2,$R29-1,1))=P29,1,0) -> 1
A30: =N30 & TEXT($O30,"000000") & TEXT($P30, "000") -> IntelMKL002510015 | B30: =N30 -> IntelMKL | C30: =O30 -> 2510 | D30: =P30 -> 15 | E30: =AVERAGE(OFFSET(data!$A$1,$Q30-1,3,$R30,1)) -> 0.128414 | F30: =MIN(OFFSET(data!$A$1,$Q30-1,3,$R30,1)) -> 0.1276 | G30: =MAX(OFFSET(data!$A$1,$Q30-1,3,$R30,1)) -> 0.133 | H30: =(G30-F30)/E30 -> 0.04205149 | I30: =AVERAGE(OFFSET(data!$A$1,$Q30-1,4,$R30,1)) -> 246.30836 | J30: =MIN(OFFSET(data!$A$1,$Q30-1,4,$R30,1)) -> 237.8559 | K30: =MAX(OFFSET(data!$A$1,$Q30-1,4,$R30,1)) -> 247.8216 | N30: =OFFSET(data!$A$1,$Q30-1,0) -> IntelMKL | O30: =OFFSET(data!$A$1,$Q30-1,1) -> 2510 | P30: =OFFSET(data!$A$1,$Q30-1,2) -> 15 | Q30: =Q29+R29+1 -> 882 | R30: 50 | S30: =IF(AVERAGE(OFFSET(data!$A$1,$Q30,1,$R30-1,1))=O30,1,0) -> 1 | T30: =IF(AVERAGE(OFFSET(data!$A$1,$Q30,2,$R30-1,1))=P30,1,0) -> 1
A31: =N31 & TEXT($O31,"000000") & TEXT($P31, "000") -> IntelMKL002510016 | B31: =N31 -> IntelMKL | C31: =O31 -> 2510 | D31: =P31 -> 16 | E31: =AVERAGE(OFFSET(data!$A$1,$Q31-1,3,$R31,1)) -> 0.154844 | F31: =MIN(OFFSET(data!$A$1,$Q31-1,3,$R31,1)) -> 0.1137 | G31: =MAX(OFFSET(data!$A$1,$Q31-1,3,$R31,1)) -> 0.2316 | H31: =(G31-F31)/E31 -> 0.76141149 | I31: =AVERAGE(OFFSET(data!$A$1,$Q31-1,4,$R31,1)) -> 223.82353 | J31: =MIN(OFFSET(data!$A$1,$Q31-1,4,$R31,1)) -> 136.5442 | K31: =MAX(OFFSET(data!$A$1,$Q31-1,4,$R31,1)) -> 278.1917 | N31: =OFFSET(data!$A$1,$Q31-1,0) -> IntelMKL | O31: =OFFSET(data!$A$1,$Q31-1,1) -> 2510 | P31: =OFFSET(data!$A$1,$Q31-1,2) -> 16 | Q31: =Q30+R30+1 -> 933 | R31: 50 | S31: =IF(AVERAGE(OFFSET(data!$A$1,$Q31,1,$R31-1,1))=O31,1,0) -> 1 | T31: =IF(AVERAGE(OFFSET(data!$A$1,$Q31,2,$R31-1,1))=P31,1,0) -> 1
A32: =N32 & TEXT($O32,"000000") & TEXT($P32, "000") -> IntelMKL010000001 | B32: =N32 -> IntelMKL | C32: =O32 -> 10000 | D32: =P32 -> 1 | E32: =AVERAGE(OFFSET(data!$A$1,$Q32-1,3,$R32,1)) -> 101.662 | F32: =MIN(OFFSET(data!$A$1,$Q32-1,3,$R32,1)) -> 101.6614 | G32: =MAX(OFFSET(data!$A$1,$Q32-1,3,$R32,1)) -> 101.6632 | H32: =(G32-F32)/E32 -> 1.7705731e-05 | I32: =AVERAGE(OFFSET(data!$A$1,$Q32-1,4,$R32,1)) -> 19.67302 | J32: =MIN(OFFSET(data!$A$1,$Q32-1,4,$R32,1)) -> 19.6728 | K32: =MAX(OFFSET(data!$A$1,$Q32-1,4,$R32,1)) -> 19.6731 | N32: =OFFSET(data!$A$1,$Q32-1,0) -> IntelMKL | O32: =OFFSET(data!$A$1,$Q32-1,1) -> 10000 | P32: =OFFSET(data!$A$1,$Q32-1,2) -> 1 | Q32: =Q31+R31+1 -> 984 | R32: 5 | S32: =IF(AVERAGE(OFFSET(data!$A$1,$Q32,1,$R32-1,1))=O32,1,0) -> 1 | T32: =IF(AVERAGE(OFFSET(data!$A$1,$Q32,2,$R32-1,1))=P32,1,0) -> 1
A33: =N33 & TEXT($O33,"000000") & TEXT($P33, "000") -> IntelMKL010000015 | B33: =N33 -> IntelMKL | C33: =O33 -> 10000 | D33: =P33 -> 15 | E33: =AVERAGE(OFFSET(data!$A$1,$Q33-1,3,$R33,1)) -> 7.555776 | F33: =MIN(OFFSET(data!$A$1,$Q33-1,3,$R33,1)) -> 7.4618 | G33: =MAX(OFFSET(data!$A$1,$Q33-1,3,$R33,1)) -> 7.6463 | H33: =(G33-F33)/E33 -> 0.024418405 | I33: =AVERAGE(OFFSET(data!$A$1,$Q33-1,4,$R33,1)) -> 264.71744 | J33: =MIN(OFFSET(data!$A$1,$Q33-1,4,$R33,1)) -> 261.5655 | K33: =MAX(OFFSET(data!$A$1,$Q33-1,4,$R33,1)) -> 268.0322 | N33: =OFFSET(data!$A$1,$Q33-1,0) -> IntelMKL | O33: =OFFSET(data!$A$1,$Q33-1,1) -> 10000 | P33: =OFFSET(data!$A$1,$Q33-1,2) -> 15 | Q33: =Q32+R32+1 -> 990 | R33: 50 | S33: =IF(AVERAGE(OFFSET(data!$A$1,$Q33,1,$R33-1,1))=O33,1,0) -> 1 | T33: =IF(AVERAGE(OFFSET(data!$A$1,$Q33,2,$R33-1,1))=P33,1,0) -> 1
A34: =N34 & TEXT($O34,"000000") & TEXT($P34, "000") -> IntelMKL010000016 | B34: =N34 -> IntelMKL | C34: =O34 -> 10000 | D34: =P34 -> 16 | E34: =AVERAGE(OFFSET(data!$A$1,$Q34-1,3,$R34,1)) -> 6.901736 | F34: =MIN(OFFSET(data!$A$1,$Q34-1,3,$R34,1)) -> 6.6454 | G34: =MAX(OFFSET(data!$A$1,$Q34-1,3,$R34,1)) -> 12.3321 | H34: =(G34-F34)/E34 -> 0.82395212 | I34: =AVERAGE(OFFSET(data!$A$1,$Q34-1,4,$R34,1)) -> 293.05729 | J34: =MIN(OFFSET(data!$A$1,$Q34-1,4,$R34,1)) -> 162.1787 | K34: =MAX(OFFSET(data!$A$1,$Q34-1,4,$R34,1)) -> 300.9607 | N34: =OFFSET(data!$A$1,$Q34-1,0) -> IntelMKL | O34: =OFFSET(data!$A$1,$Q34-1,1) -> 10000 | P34: =OFFSET(data!$A$1,$Q34-1,2) -> 16 | Q34: =Q33+R33+1 -> 1041 | R34: 50 | S34: =IF(AVERAGE(OFFSET(data!$A$1,$Q34,1,$R34-1,1))=O34,1,0) -> 1 | T34: =IF(AVERAGE(OFFSET(data!$A$1,$Q34,2,$R34-1,1))=P34,1,0) -> 1
A35: =N35 & TEXT($O35,"000000") & TEXT($P35, "000") -> IntelMKL010005001 | B35: =N35 -> IntelMKL | C35: =O35 -> 10005 | D35: =P35 -> 1 | E35: =AVERAGE(OFFSET(data!$A$1,$Q35-1,3,$R35,1)) -> 102.3647 | F35: =MIN(OFFSET(data!$A$1,$Q35-1,3,$R35,1)) -> 102.364 | G35: =MAX(OFFSET(data!$A$1,$Q35-1,3,$R35,1)) -> 102.3656 | H35: =(G35-F35)/E35 -> 1.5630388e-05 | I35: =AVERAGE(OFFSET(data!$A$1,$Q35-1,4,$R35,1)) -> 19.5673 | J35: =MIN(OFFSET(data!$A$1,$Q35-1,4,$R35,1)) -> 19.5671 | K35: =MAX(OFFSET(data!$A$1,$Q35-1,4,$R35,1)) -> 19.5674 | N35: =OFFSET(data!$A$1,$Q35-1,0) -> IntelMKL | O35: =OFFSET(data!$A$1,$Q35-1,1) -> 10005 | P35: =OFFSET(data!$A$1,$Q35-1,2) -> 1 | Q35: =Q34+R34+1 -> 1092 | R35: 5 | S35: =IF(AVERAGE(OFFSET(data!$A$1,$Q35,1,$R35-1,1))=O35,1,0) -> 1 | T35: =IF(AVERAGE(OFFSET(data!$A$1,$Q35,2,$R35-1,1))=P35,1,0) -> 1
... A40: =N40 & TEXT($O40,"000000") & TEXT($P40, "000") -> IntelMKL010010016 | B40: =N40 -> IntelMKL | C40: =O40 -> 10010 | D40: =P40 -> 16 | E40: =AVERAGE(OFFSET(data!$A$1,$Q40-1,3,$R40,1)) -> 6.860304 | F40: =MIN(OFFSET(data!$A$1,$Q40-1,3,$R40,1)) -> 6.6039 | G40: =MAX(OFFSET(data!$A$1,$Q40-1,3,$R40,1)) -> 12.4107 | H40: =(G40-F40)/E40 -> 0.84643479 | I40: =AVERAGE(OFFSET(data!$A$1,$Q40-1,4,$R40,1)) -> 295.81011 | J40: =MIN(OFFSET(data!$A$1,$Q40-1,4,$R40,1)) -> 161.6349 | K40: =MAX(OFFSET(data!$A$1,$Q40-1,4,$R40,1)) -> 303.7626 | N40: =OFFSET(data!$A$1,$Q40-1,0) -> IntelMKL | O40: =OFFSET(data!$A$1,$Q40-1,1) -> 10010 | P40: =OFFSET(data!$A$1,$Q40-1,2) -> 16 | Q40: =Q39+R39+1 -> 1257 | R40: 50 | S40: =IF(AVERAGE(OFFSET(data!$A$1,$Q40,1,$R40-1,1))=O40,1,0) -> 1 | T40: =IF(AVERAGE(OFFSET(data!$A$1,$Q40,2,$R40-1,1))=P40,1,0) -> 1
D47: Speling tijd | G47: Gflops
B48: Variuant | C48: Size | D48: =D5 -> 1 | E48: =D6 -> 15 | F48: =D7 -> 16 | G48: =D5 -> 1 | H48: =D6 -> 15 | I48: =D7 -> 16
B49: =B5 -> OpenBLAS | C49: =C5 -> 2500 | D49: =VLOOKUP(N49,datatable,8,FALSE) -> 0.011710468 | E49: =VLOOKUP(O49,datatable,8,FALSE) -> 0.048319294 | F49: =VLOOKUP(P49,datatable,8,FALSE) -> 0.56578064 | G49: =VLOOKUP(N49,datatable,9,FALSE) -> 19.26112 | H49: =VLOOKUP(O49,datatable,9,FALSE) -> 251.70313 | I49: =VLOOKUP(P49,datatable,9,FALSE) -> 160.7458 | N49: =$B49 & TEXT($C49,"000000") & TEXT(D$48,"000") -> OpenBLAS002500001 | O49: =$B49 & TEXT($C49,"000000") & TEXT(E$48,"000") -> OpenBLAS002500015 | P49: =$B49 & TEXT($C49,"000000") & TEXT(F$48,"000") -> OpenBLAS002500016
B50: =B8 -> OpenBLAS | C50: =C8 -> 2505 | D50: =VLOOKUP(N50,datatable,8,FALSE) -> 6.1305313e-05 | E50: =VLOOKUP(O50,datatable,8,FALSE) -> 0.02094747 | F50: =VLOOKUP(P50,datatable,8,FALSE) -> 0.14459963 | G50: =VLOOKUP(N50,datatable,9,FALSE) -> 19.27274 | H50: =VLOOKUP(O50,datatable,9,FALSE) -> 253.28069 | I50: =VLOOKUP(P50,datatable,9,FALSE) -> 267.63091 | N50: =$B50 & TEXT($C50,"000000") & TEXT(D$48,"000") -> OpenBLAS002505001 | O50: =$B50 & TEXT($C50,"000000") & TEXT(E$48,"000") -> OpenBLAS002505015 | P50: =$B50 & TEXT($C50,"000000") & TEXT(F$48,"000") -> OpenBLAS002505016
B51: =B11 -> OpenBLAS | C51: =C11 -> 2510 | D51: =VLOOKUP(N51,datatable,8,FALSE) -> 0.00012276566 | E51: =VLOOKUP(O51,datatable,8,FALSE) -> 0.0073653371 | F51: =VLOOKUP(P51,datatable,8,FALSE) -> 0.063845159 | G51: =VLOOKUP(N51,datatable,9,FALSE) -> 19.41332 | H51: =VLOOKUP(O51,datatable,9,FALSE) -> 258.82319 | I51: =VLOOKUP(P51,datatable,9,FALSE) -> 265.71807 | N51: =$B51 & TEXT($C51,"000000") & TEXT(D$48,"000") -> OpenBLAS002510001 | O51: =$B51 & TEXT($C51,"000000") & TEXT(E$48,"000") -> OpenBLAS002510015 | P51: =$B51 & TEXT($C51,"000000") & TEXT(F$48,"000") -> OpenBLAS002510016
B52: =B14 -> OpenBLAS | C52: =C14 -> 10000 | D52: =VLOOKUP(N52,datatable,8,FALSE) -> 0.0048854767 | E52: =VLOOKUP(O52,datatable,8,FALSE) -> 0.0066991376 | F52: =VLOOKUP(P52,datatable,8,FALSE) -> 0.72554408 | G52: =VLOOKUP(N52,datatable,9,FALSE) -> 19.51466 | H52: =VLOOKUP(O52,datatable,9,FALSE) -> 277.97333 | I52: =VLOOKUP(P52,datatable,9,FALSE) -> 288.90371 | N52: =$B52 & TEXT($C52,"000000") & TEXT(D$48,"000") -> OpenBLAS010000001 | O52: =$B52 & TEXT($C52,"000000") & TEXT(E$48,"000") -> OpenBLAS010000015 | P52: =$B52 & TEXT($C52,"000000") & TEXT(F$48,"000") -> OpenBLAS010000016
B53: =B17 -> OpenBLAS | C53: =C17 -> 10005 | D53: =VLOOKUP(N53,datatable,8,FALSE) -> 7.7512455e-05 | E53: =VLOOKUP(O53,datatable,8,FALSE) -> 0.024229903 | F53: =VLOOKUP(P53,datatable,8,FALSE) -> 0.74924455 | G53: =VLOOKUP(N53,datatable,9,FALSE) -> 19.4072 | H53: =VLOOKUP(O53,datatable,9,FALSE) -> 276.54203 | I53: =VLOOKUP(P53,datatable,9,FALSE) -> 287.22814 | N53: =$B53 & TEXT($C53,"000000") & TEXT(D$48,"000") -> OpenBLAS010005001 | O53: =$B53 & TEXT($C53,"000000") & TEXT(E$48,"000") -> OpenBLAS010005015 | P53: =$B53 & TEXT($C53,"000000") & TEXT(F$48,"000") -> OpenBLAS010005016
B54: =B20 -> OpenBLAS | C54: =C20 -> 10010 | D54: =VLOOKUP(N54,datatable,8,FALSE) -> 0.00023020707 | E54: =VLOOKUP(O54,datatable,8,FALSE) -> 0.01078909 | F54: =VLOOKUP(P54,datatable,8,FALSE) -> 0.70659322 | G54: =VLOOKUP(N54,datatable,9,FALSE) -> 19.56766 | H54: =VLOOKUP(O54,datatable,9,FALSE) -> 279.26537 | I54: =VLOOKUP(P54,datatable,9,FALSE) -> 291.31797 | N54: =$B54 & TEXT($C54,"000000") & TEXT(D$48,"000") -> OpenBLAS010010001 | O54: =$B54 & TEXT($C54,"000000") & TEXT(E$48,"000") -> OpenBLAS010010015 | P54: =$B54 & TEXT($C54,"000000") & TEXT(F$48,"000") -> OpenBLAS010010016
B55: =B23 -> IntelMKL | C55: =C23 -> 2500 | D55: =VLOOKUP(N55,datatable,8,FALSE) -> 6.2365135e-05 | E55: =VLOOKUP(O55,datatable,8,FALSE) -> 0.0024178339 | F55: =VLOOKUP(P55,datatable,8,FALSE) -> 0.035111095 | G55: =VLOOKUP(N55,datatable,9,FALSE) -> 19.48908 | H55: =VLOOKUP(O55,datatable,9,FALSE) -> 251.86468 | I55: =VLOOKUP(P55,datatable,9,FALSE) -> 281.34522 | N55: =$B55 & TEXT($C55,"000000") & TEXT(D$48,"000") -> IntelMKL002500001 | O55: =$B55 & TEXT($C55,"000000") & TEXT(E$48,"000") -> IntelMKL002500015 | P55: =$B55 & TEXT($C55,"000000") & TEXT(F$48,"000") -> IntelMKL002500016
...
